    response = wrapped_callback(request, *callback_args, **callback_kwargs)
               ^^^^^^^^^^^^^^^^^^^^^^^^^^^^^^^^^^^^^^^^^^^^^^^^^^^^^^^^^^^^
  File "/home/isty/mini-crm-realty/core/views.py", line 330, in panel_edit
    _panel_form_context(form, prop, list(prop.photos.all())),
                                    ^^^^^^^^^^^^^^^^^^^^^^^
  File "/home/isty/mini-crm-realty/venv/lib/python3.12/site-packages/django/db/models/query.py", line 384, in __iter__
    self._fetch_all()
  File "/home/isty/mini-crm-realty/venv/lib/python3.12/site-packages/django/db/models/query.py", line 1949, in _fetch_all
    self._result_cache = list(self._iterable_class(self))
                         ^^^^^^^^^^^^^^^^^^^^^^^^^^^^^^^^
  File "/home/isty/mini-crm-realty/venv/lib/python3.12/site-packages/django/db/models/query.py", line 91, in __iter__
    results = compiler.execute_sql(
              ^^^^^^^^^^^^^^^^^^^^^
  File "/home/isty/mini-crm-realty/venv/lib/python3.12/site-packages/django/db/models/sql/compiler.py", line 1623, in execute_sql
    cursor.execute(sql, params)
  File "/home/isty/mini-crm-realty/venv/lib/python3.12/site-packages/django/db/backends/utils.py", line 79, in execute
    return self._execute_with_wrappers(
           ^^^^^^^^^^^^^^^^^^^^^^^^^^^^
  File "/home/isty/mini-crm-realty/venv/lib/python3.12/site-packages/django/db/backends/utils.py", line 92, in _execute_with_wrappers
    return executor(sql, params, many, context)
           ^^^^^^^^^^^^^^^^^^^^^^^^^^^^^^^^^^^^
  File "/home/isty/mini-crm-realty/venv/lib/python3.12/site-packages/django/db/backends/utils.py", line 100, in _execute
    with self.db.wrap_database_errors:
         ^^^^^^^^^^^^^^^^^^^^^^^^^^^^
  File "/home/isty/mini-crm-realty/venv/lib/python3.12/site-packages/django/db/utils.py", line 91, in __exit__
    raise dj_exc_value.with_traceback(traceback) from exc_value
  File "/home/isty/mini-crm-realty/venv/lib/python3.12/site-packages/django/db/backends/utils.py", line 105, in _execute
    return self.cursor.execute(sql, params)
           ^^^^^^^^^^^^^^^^^^^^^^^^^^^^^^^^
  File "/home/isty/mini-crm-realty/venv/lib/python3.12/site-packages/django/db/backends/sqlite3/base.py", line 360, in execute
    return super().execute(query, params)
           ^^^^^^^^^^^^^^^^^^^^^^^^^^^^^^
django.db.utils.OperationalError: no such column: core_photo.url
2025-10-07 19:15:46,940: Not Found: /
2025-10-07 19:15:56,398: Internal Server Error: /panel/edit/3/
Traceback (most recent call last):
  File "/home/isty/mini-crm-realty/venv/lib/python3.12/site-packages/django/db/backends/utils.py", line 105, in _execute
    return self.cursor.execute(sql, params)
           ^^^^^^^^^^^^^^^^^^^^^^^^^^^^^^^^
  File "/home/isty/mini-crm-realty/venv/lib/python3.12/site-packages/django/db/backends/sqlite3/base.py", line 360, in execute
    return super().execute(query, params)
           ^^^^^^^^^^^^^^^^^^^^^^^^^^^^^^
sqlite3.OperationalError: no such column: core_photo.url
**NO MATCH**
The above exception was the direct cause of the following exception:
**NO MATCH**
Traceback (most recent call last):
  File "/home/isty/mini-crm-realty/venv/lib/python3.12/site-packages/django/core/handlers/exception.py", line 55, in inner
    response = get_response(request)
               ^^^^^^^^^^^^^^^^^^^^^
  File "/home/isty/mini-crm-realty/venv/lib/python3.12/site-packages/django/core/handlers/base.py", line 197, in _get_response
    response = wrapped_callback(request, *callback_args, **callback_kwargs)
               ^^^^^^^^^^^^^^^^^^^^^^^^^^^^^^^^^^^^^^^^^^^^^^^^^^^^^^^^^^^^
  File "/home/isty/mini-crm-realty/core/views.py", line 368, in panel_edit
    _panel_form_context(form, prop, list(prop.photos.all())),
                                    ^^^^^^^^^^^^^^^^^^^^^^^
  File "/home/isty/mini-crm-realty/venv/lib/python3.12/site-packages/django/db/models/query.py", line 384, in __iter__
    self._fetch_all()
  File "/home/isty/mini-crm-realty/venv/lib/python3.12/site-packages/django/db/models/query.py", line 1949, in _fetch_all
    self._result_cache = list(self._iterable_class(self))
                         ^^^^^^^^^^^^^^^^^^^^^^^^^^^^^^^^
  File "/home/isty/mini-crm-realty/venv/lib/python3.12/site-packages/django/db/models/query.py", line 91, in __iter__
    results = compiler.execute_sql(
              ^^^^^^^^^^^^^^^^^^^^^
  File "/home/isty/mini-crm-realty/venv/lib/python3.12/site-packages/django/db/models/sql/compiler.py", line 1623, in execute_sql
    cursor.execute(sql, params)
  File "/home/isty/mini-crm-realty/venv/lib/python3.12/site-packages/django/db/backends/utils.py", line 79, in execute
    return self._execute_with_wrappers(
           ^^^^^^^^^^^^^^^^^^^^^^^^^^^^
  File "/home/isty/mini-crm-realty/venv/lib/python3.12/site-packages/django/db/backends/utils.py", line 92, in _execute_with_wrappers
    return executor(sql, params, many, context)
           ^^^^^^^^^^^^^^^^^^^^^^^^^^^^^^^^^^^^
  File "/home/isty/mini-crm-realty/venv/lib/python3.12/site-packages/django/db/backends/utils.py", line 100, in _execute
    with self.db.wrap_database_errors:
         ^^^^^^^^^^^^^^^^^^^^^^^^^^^^
  File "/home/isty/mini-crm-realty/venv/lib/python3.12/site-packages/django/db/utils.py", line 91, in __exit__
    raise dj_exc_value.with_traceback(traceback) from exc_value
  File "/home/isty/mini-crm-realty/venv/lib/python3.12/site-packages/django/db/backends/utils.py", line 105, in _execute
    return self.cursor.execute(sql, params)
           ^^^^^^^^^^^^^^^^^^^^^^^^^^^^^^^^
  File "/home/isty/mini-crm-realty/venv/lib/python3.12/site-packages/django/db/backends/sqlite3/base.py", line 360, in execute
    return super().execute(query, params)
           ^^^^^^^^^^^^^^^^^^^^^^^^^^^^^^
django.db.utils.OperationalError: no such column: core_photo.url
2025-10-07 19:16:35,985: Internal Server Error: /panel/edit/3/
Traceback (most recent call last):
  File "/home/isty/mini-crm-realty/venv/lib/python3.12/site-packages/django/db/backends/utils.py", line 105, in _execute
    return self.cursor.execute(sql, params)
           ^^^^^^^^^^^^^^^^^^^^^^^^^^^^^^^^
  File "/home/isty/mini-crm-realty/venv/lib/python3.12/site-packages/django/db/backends/sqlite3/base.py", line 360, in execute
    return super().execute(query, params)
           ^^^^^^^^^^^^^^^^^^^^^^^^^^^^^^
sqlite3.OperationalError: no such column: core_photo.url
**NO MATCH**
The above exception was the direct cause of the following exception:
**NO MATCH**
Traceback (most recent call last):
  File "/home/isty/mini-crm-realty/venv/lib/python3.12/site-packages/django/core/handlers/exception.py", line 55, in inner
    response = get_response(request)
               ^^^^^^^^^^^^^^^^^^^^^
  File "/home/isty/mini-crm-realty/venv/lib/python3.12/site-packages/django/core/handlers/base.py", line 197, in _get_response
    response = wrapped_callback(request, *callback_args, **callback_kwargs)
               ^^^^^^^^^^^^^^^^^^^^^^^^^^^^^^^^^^^^^^^^^^^^^^^^^^^^^^^^^^^^
  File "/home/isty/mini-crm-realty/core/views.py", line 368, in panel_edit
    _panel_form_context(form, prop, list(prop.photos.all())),
                                    ^^^^^^^^^^^^^^^^^^^^^^^
  File "/home/isty/mini-crm-realty/venv/lib/python3.12/site-packages/django/db/models/query.py", line 384, in __iter__
    self._fetch_all()
  File "/home/isty/mini-crm-realty/venv/lib/python3.12/site-packages/django/db/models/query.py", line 1949, in _fetch_all
    self._result_cache = list(self._iterable_class(self))
                         ^^^^^^^^^^^^^^^^^^^^^^^^^^^^^^^^
  File "/home/isty/mini-crm-realty/venv/lib/python3.12/site-packages/django/db/models/query.py", line 91, in __iter__
    results = compiler.execute_sql(
              ^^^^^^^^^^^^^^^^^^^^^
  File "/home/isty/mini-crm-realty/venv/lib/python3.12/site-packages/django/db/models/sql/compiler.py", line 1623, in execute_sql
    cursor.execute(sql, params)
  File "/home/isty/mini-crm-realty/venv/lib/python3.12/site-packages/django/db/backends/utils.py", line 79, in execute
    return self._execute_with_wrappers(
           ^^^^^^^^^^^^^^^^^^^^^^^^^^^^
  File "/home/isty/mini-crm-realty/venv/lib/python3.12/site-packages/django/db/backends/utils.py", line 92, in _execute_with_wrappers
    return executor(sql, params, many, context)
           ^^^^^^^^^^^^^^^^^^^^^^^^^^^^^^^^^^^^
  File "/home/isty/mini-crm-realty/venv/lib/python3.12/site-packages/django/db/backends/utils.py", line 100, in _execute
    with self.db.wrap_database_errors:
         ^^^^^^^^^^^^^^^^^^^^^^^^^^^^
  File "/home/isty/mini-crm-realty/venv/lib/python3.12/site-packages/django/db/utils.py", line 91, in __exit__
    raise dj_exc_value.with_traceback(traceback) from exc_value
  File "/home/isty/mini-crm-realty/venv/lib/python3.12/site-packages/django/db/backends/utils.py", line 105, in _execute
    return self.cursor.execute(sql, params)
           ^^^^^^^^^^^^^^^^^^^^^^^^^^^^^^^^
  File "/home/isty/mini-crm-realty/venv/lib/python3.12/site-packages/django/db/backends/sqlite3/base.py", line 360, in execute
    return super().execute(query, params)
           ^^^^^^^^^^^^^^^^^^^^^^^^^^^^^^
django.db.utils.OperationalError: no such column: core_photo.url
2025-10-07 19:17:10,786: Internal Server Error: /panel/edit/2/
Traceback (most recent call last):
  File "/home/isty/mini-crm-realty/venv/lib/python3.12/site-packages/django/db/backends/utils.py", line 105, in _execute
    return self.cursor.execute(sql, params)
           ^^^^^^^^^^^^^^^^^^^^^^^^^^^^^^^^
  File "/home/isty/mini-crm-realty/venv/lib/python3.12/site-packages/django/db/backends/sqlite3/base.py", line 360, in execute
    return super().execute(query, params)
           ^^^^^^^^^^^^^^^^^^^^^^^^^^^^^^
sqlite3.OperationalError: no such column: core_photo.url
**NO MATCH**
The above exception was the direct cause of the following exception:
**NO MATCH**
Traceback (most recent call last):
  File "/home/isty/mini-crm-realty/venv/lib/python3.12/site-packages/django/core/handlers/exception.py", line 55, in inner
    response = get_response(request)
               ^^^^^^^^^^^^^^^^^^^^^
  File "/home/isty/mini-crm-realty/venv/lib/python3.12/site-packages/django/core/handlers/base.py", line 197, in _get_response
    response = wrapped_callback(request, *callback_args, **callback_kwargs)
               ^^^^^^^^^^^^^^^^^^^^^^^^^^^^^^^^^^^^^^^^^^^^^^^^^^^^^^^^^^^^
  File "/home/isty/mini-crm-realty/core/views.py", line 368, in panel_edit
    _panel_form_context(form, prop, list(prop.photos.all())),
                                    ^^^^^^^^^^^^^^^^^^^^^^^
  File "/home/isty/mini-crm-realty/venv/lib/python3.12/site-packages/django/db/models/query.py", line 384, in __iter__
    self._fetch_all()
  File "/home/isty/mini-crm-realty/venv/lib/python3.12/site-packages/django/db/models/query.py", line 1949, in _fetch_all
    self._result_cache = list(self._iterable_class(self))
                         ^^^^^^^^^^^^^^^^^^^^^^^^^^^^^^^^
  File "/home/isty/mini-crm-realty/venv/lib/python3.12/site-packages/django/db/models/query.py", line 91, in __iter__
    results = compiler.execute_sql(
              ^^^^^^^^^^^^^^^^^^^^^
  File "/home/isty/mini-crm-realty/venv/lib/python3.12/site-packages/django/db/models/sql/compiler.py", line 1623, in execute_sql
    cursor.execute(sql, params)
  File "/home/isty/mini-crm-realty/venv/lib/python3.12/site-packages/django/db/backends/utils.py", line 79, in execute
    return self._execute_with_wrappers(
           ^^^^^^^^^^^^^^^^^^^^^^^^^^^^
  File "/home/isty/mini-crm-realty/venv/lib/python3.12/site-packages/django/db/backends/utils.py", line 92, in _execute_with_wrappers
    return executor(sql, params, many, context)
           ^^^^^^^^^^^^^^^^^^^^^^^^^^^^^^^^^^^^
  File "/home/isty/mini-crm-realty/venv/lib/python3.12/site-packages/django/db/backends/utils.py", line 100, in _execute
    with self.db.wrap_database_errors:
         ^^^^^^^^^^^^^^^^^^^^^^^^^^^^
  File "/home/isty/mini-crm-realty/venv/lib/python3.12/site-packages/django/db/utils.py", line 91, in __exit__
    raise dj_exc_value.with_traceback(traceback) from exc_value
  File "/home/isty/mini-crm-realty/venv/lib/python3.12/site-packages/django/db/backends/utils.py", line 105, in _execute
    return self.cursor.execute(sql, params)
           ^^^^^^^^^^^^^^^^^^^^^^^^^^^^^^^^
  File "/home/isty/mini-crm-realty/venv/lib/python3.12/site-packages/django/db/backends/sqlite3/base.py", line 360, in execute
    return super().execute(query, params)
           ^^^^^^^^^^^^^^^^^^^^^^^^^^^^^^
django.db.utils.OperationalError: no such column: core_photo.url
2025-10-07 19:18:14,200: Internal Server Error: /panel/edit/1/
Traceback (most recent call last):
  File "/home/isty/mini-crm-realty/venv/lib/python3.12/site-packages/django/db/backends/utils.py", line 105, in _execute
    return self.cursor.execute(sql, params)
           ^^^^^^^^^^^^^^^^^^^^^^^^^^^^^^^^
  File "/home/isty/mini-crm-realty/venv/lib/python3.12/site-packages/django/db/backends/sqlite3/base.py", line 360, in execute
    return super().execute(query, params)
           ^^^^^^^^^^^^^^^^^^^^^^^^^^^^^^
sqlite3.OperationalError: no such column: core_photo.url
**NO MATCH**
The above exception was the direct cause of the following exception:
**NO MATCH**
Traceback (most recent call last):
  File "/home/isty/mini-crm-realty/venv/lib/python3.12/site-packages/django/core/handlers/exception.py", line 55, in inner
    response = get_response(request)
               ^^^^^^^^^^^^^^^^^^^^^
  File "/home/isty/mini-crm-realty/venv/lib/python3.12/site-packages/django/core/handlers/base.py", line 197, in _get_response
    response = wrapped_callback(request, *callback_args, **callback_kwargs)
               ^^^^^^^^^^^^^^^^^^^^^^^^^^^^^^^^^^^^^^^^^^^^^^^^^^^^^^^^^^^^
  File "/home/isty/mini-crm-realty/core/views.py", line 368, in panel_edit
    _panel_form_context(form, prop, list(prop.photos.all())),
                                    ^^^^^^^^^^^^^^^^^^^^^^^
  File "/home/isty/mini-crm-realty/venv/lib/python3.12/site-packages/django/db/models/query.py", line 384, in __iter__
    self._fetch_all()
  File "/home/isty/mini-crm-realty/venv/lib/python3.12/site-packages/django/db/models/query.py", line 1949, in _fetch_all
    self._result_cache = list(self._iterable_class(self))
                         ^^^^^^^^^^^^^^^^^^^^^^^^^^^^^^^^
  File "/home/isty/mini-crm-realty/venv/lib/python3.12/site-packages/django/db/models/query.py", line 91, in __iter__
    results = compiler.execute_sql(
              ^^^^^^^^^^^^^^^^^^^^^
  File "/home/isty/mini-crm-realty/venv/lib/python3.12/site-packages/django/db/models/sql/compiler.py", line 1623, in execute_sql
    cursor.execute(sql, params)
  File "/home/isty/mini-crm-realty/venv/lib/python3.12/site-packages/django/db/backends/utils.py", line 79, in execute
    return self._execute_with_wrappers(
           ^^^^^^^^^^^^^^^^^^^^^^^^^^^^
  File "/home/isty/mini-crm-realty/venv/lib/python3.12/site-packages/django/db/backends/utils.py", line 92, in _execute_with_wrappers
    return executor(sql, params, many, context)
           ^^^^^^^^^^^^^^^^^^^^^^^^^^^^^^^^^^^^
  File "/home/isty/mini-crm-realty/venv/lib/python3.12/site-packages/django/db/backends/utils.py", line 100, in _execute
    with self.db.wrap_database_errors:
         ^^^^^^^^^^^^^^^^^^^^^^^^^^^^
  File "/home/isty/mini-crm-realty/venv/lib/python3.12/site-packages/django/db/utils.py", line 91, in __exit__
    raise dj_exc_value.with_traceback(traceback) from exc_value
  File "/home/isty/mini-crm-realty/venv/lib/python3.12/site-packages/django/db/backends/utils.py", line 105, in _execute
    return self.cursor.execute(sql, params)
           ^^^^^^^^^^^^^^^^^^^^^^^^^^^^^^^^
  File "/home/isty/mini-crm-realty/venv/lib/python3.12/site-packages/django/db/backends/sqlite3/base.py", line 360, in execute
    return super().execute(query, params)
           ^^^^^^^^^^^^^^^^^^^^^^^^^^^^^^
django.db.utils.OperationalError: no such column: core_photo.url
2025-10-07 19:33:27,722: Not Found: /
2025-10-07 19:34:00,595: Internal Server Error: /panel/edit/1/add-photo/
Traceback (most recent call last):
  File "/home/isty/mini-crm-realty/venv/lib/python3.12/site-packages/django/db/backends/utils.py", line 105, in _execute
    return self.cursor.execute(sql, params)
           ^^^^^^^^^^^^^^^^^^^^^^^^^^^^^^^^
  File "/home/isty/mini-crm-realty/venv/lib/python3.12/site-packages/django/db/backends/sqlite3/base.py", line 360, in execute
    return super().execute(query, params)
           ^^^^^^^^^^^^^^^^^^^^^^^^^^^^^^
sqlite3.IntegrityError: NOT NULL constraint failed: core_photo.full_url
**NO MATCH**
The above exception was the direct cause of the following exception:
**NO MATCH**
Traceback (most recent call last):
  File "/home/isty/mini-crm-realty/venv/lib/python3.12/site-packages/django/core/handlers/exception.py", line 55, in inner
    response = get_response(request)
               ^^^^^^^^^^^^^^^^^^^^^
  File "/home/isty/mini-crm-realty/venv/lib/python3.12/site-packages/django/core/handlers/base.py", line 197, in _get_response
    response = wrapped_callback(request, *callback_args, **callback_kwargs)
               ^^^^^^^^^^^^^^^^^^^^^^^^^^^^^^^^^^^^^^^^^^^^^^^^^^^^^^^^^^^^
  File "/home/isty/mini-crm-realty/core/views.py", line 400, in panel_add_photo
    ph.save()
  File "/home/isty/mini-crm-realty/core/models.py", line 323, in save
    super().save(*args, **kwargs)
  File "/home/isty/mini-crm-realty/venv/lib/python3.12/site-packages/django/db/models/base.py", line 902, in save
    self.save_base(
  File "/home/isty/mini-crm-realty/venv/lib/python3.12/site-packages/django/db/models/base.py", line 1008, in save_base
    updated = self._save_table(
              ^^^^^^^^^^^^^^^^^
  File "/home/isty/mini-crm-realty/venv/lib/python3.12/site-packages/django/db/models/base.py", line 1169, in _save_table
    results = self._do_insert(
              ^^^^^^^^^^^^^^^^
  File "/home/isty/mini-crm-realty/venv/lib/python3.12/site-packages/django/db/models/base.py", line 1210, in _do_insert
    return manager._insert(
           ^^^^^^^^^^^^^^^^
  File "/home/isty/mini-crm-realty/venv/lib/python3.12/site-packages/django/db/models/manager.py", line 87, in manager_method
    return getattr(self.get_queryset(), name)(*args, **kwargs)
           ^^^^^^^^^^^^^^^^^^^^^^^^^^^^^^^^^^^^^^^^^^^^^^^^^^^
  File "/home/isty/mini-crm-realty/venv/lib/python3.12/site-packages/django/db/models/query.py", line 1868, in _insert
    return query.get_compiler(using=using).execute_sql(returning_fields)
           ^^^^^^^^^^^^^^^^^^^^^^^^^^^^^^^^^^^^^^^^^^^^^^^^^^^^^^^^^^^^^
  File "/home/isty/mini-crm-realty/venv/lib/python3.12/site-packages/django/db/models/sql/compiler.py", line 1882, in execute_sql
    cursor.execute(sql, params)
  File "/home/isty/mini-crm-realty/venv/lib/python3.12/site-packages/django/db/backends/utils.py", line 79, in execute
    return self._execute_with_wrappers(
           ^^^^^^^^^^^^^^^^^^^^^^^^^^^^
  File "/home/isty/mini-crm-realty/venv/lib/python3.12/site-packages/django/db/backends/utils.py", line 92, in _execute_with_wrappers
    return executor(sql, params, many, context)
           ^^^^^^^^^^^^^^^^^^^^^^^^^^^^^^^^^^^^
  File "/home/isty/mini-crm-realty/venv/lib/python3.12/site-packages/django/db/backends/utils.py", line 100, in _execute
    with self.db.wrap_database_errors:
         ^^^^^^^^^^^^^^^^^^^^^^^^^^^^
  File "/home/isty/mini-crm-realty/venv/lib/python3.12/site-packages/django/db/utils.py", line 91, in __exit__
    raise dj_exc_value.with_traceback(traceback) from exc_value
  File "/home/isty/mini-crm-realty/venv/lib/python3.12/site-packages/django/db/backends/utils.py", line 105, in _execute
    return self.cursor.execute(sql, params)
           ^^^^^^^^^^^^^^^^^^^^^^^^^^^^^^^^
  File "/home/isty/mini-crm-realty/venv/lib/python3.12/site-packages/django/db/backends/sqlite3/base.py", line 360, in execute
    return super().execute(query, params)
           ^^^^^^^^^^^^^^^^^^^^^^^^^^^^^^
django.db.utils.IntegrityError: NOT NULL constraint failed: core_photo.full_url
2025-10-07 19:38:41,341: Not Found: /
2025-10-07 19:40:49,129: Not Found: /robots.txt
2025-10-08 05:50:35,502: Not Found: /
2025-10-08 06:20:40,191: Not Found: /
2025-10-08 06:23:56,530: Not Found: /
